<?xml version="1.0" encoding="utf-8"?>
<!-- This URDF was automatically created by SolidWorks to URDF Exporter! Originally created by Stephen Brawner (brawner@gmail.com) 
     Commit Version: 1.6.0-1-g15f4949  Build Version: 1.6.7594.29634
     For more information, please see http://wiki.ros.org/sw_urdf_exporter -->
<robot
        name="arena_model" xmlns:xacro="http://wiki.ros.org/xacro">
    <link name="base_link">
        <inertial>
            <origin
                    xyz="0.0116421064959206 -1.57531536043144E-05 0.0229823586619881"
                    rpy="0 0 0"/>
            <mass
                    value="2.24756670666722"/>
            <inertia
                    ixx="0.00788833588895297"
                    ixy="1.59481545353377E-07"
                    ixz="0.000733932077942135"
                    iyy="0.00652199128909781"
                    iyz="2.90926203156588E-07"
                    izz="0.0130391055308841"/>
        </inertial>
        <visual>
            <origin
                    xyz="0 0 0"
                    rpy="0 0 0"/>
            <geometry>
                <mesh
                        filename="package://arena_model/meshes/base_link.STL"/>
            </geometry>
            <material
                    name="">
                <color
                        rgba="0.752941176470588 0.752941176470588 0.752941176470588 1"/>
            </material>
        </visual>
        <collision>
            <origin
                    xyz="0 0 0"
                    rpy="0 0 0"/>
            <geometry>
                <mesh
                        filename="package://arena_model/meshes/base_link.STL"/>
            </geometry>
        </collision>
    </link>
<!--    <joint name="LB_wheel_joint"-->
<!--            type="continuous">-->
<!--        <origin-->
<!--                xyz="-0.051575 0.1185 0.017"-->
<!--                rpy="0 0 0"/>-->
<!--        <parent-->
<!--                link="base_link"/>-->
<!--        <child-->
<!--                link="LB_wheel_link"/>-->
<!--        <axis-->
<!--                xyz="0 -1 0"/>-->
<!--    </joint>-->
    <link name="RF_wheel_link">
        <inertial>
            <origin
                    xyz="2.77555756156289E-17 0.0144155178676929 1.38777878078145E-17"
                    rpy="0 0 0"/>
            <mass
                    value="0.12660325610778"/>
            <inertia
                    ixx="5.54515308491946E-05"
                    ixy="9.8493461627243E-21"
                    ixz="5.09596618673687E-20"
                    iyy="0.000103691650811599"
                    iyz="2.67643313336152E-21"
                    izz="5.54515308491945E-05"/>
        </inertial>
        <visual>
            <origin
                    xyz="0 0 0"
                    rpy="0 0 0"/>
            <geometry>
                <mesh
                        filename="package://arena_model/meshes/RF_wheel_link.STL"/>
            </geometry>
            <material
                    name="">
                <color
                        rgba="0.752941176470588 0.752941176470588 0.752941176470588 1"/>
            </material>
        </visual>
        <collision>
            <origin
                    xyz="0 0 0"
                    rpy="0 0 0"/>
            <geometry>
                <mesh
                        filename="package://arena_model/meshes/RF_wheel_link.STL"/>
            </geometry>
        </collision>
    </link>
    <joint name="RF_wheel_joint" type="continuous">
        <origin
                xyz="0.0784235230362508 -0.1185 0.017"
                rpy="0 0 0"/>
        <parent
                link="base_link"/>
        <child
                link="RF_wheel_link"/>
        <axis
                xyz="0 1 0"/>
    </joint>
    <link name="RB_wheel_link">
        <inertial>
            <origin
                    xyz="6.93889390390723E-18 0.0144155178676929 1.73472347597681E-17"
                    rpy="0 0 0"/>
            <mass
                    value="0.12660325610778"/>
            <inertia
                    ixx="5.54515308491959E-05"
                    ixy="6.62179075999811E-21"
                    ixz="4.71426805732122E-20"
                    iyy="0.000103691650811599"
                    iyz="6.86755842269828E-21"
                    izz="5.54515308491959E-05"/>
        </inertial>
        <visual>
            <origin
                    xyz="0 0 0"
                    rpy="0 0 0"/>
            <geometry>
                <mesh
                        filename="package://arena_model/meshes/RB_wheel_link.STL"/>
            </geometry>
            <material
                    name="">
                <color
                        rgba="0.752941176470588 0.752941176470588 0.752941176470588 1"/>
            </material>
        </visual>
        <collision>
            <origin
                    xyz="0 0 0"
                    rpy="0 0 0"/>
            <geometry>
                <mesh
                        filename="package://arena_model/meshes/RB_wheel_link.STL"/>
            </geometry>
        </collision>
    </link>
    <joint name="RB_wheel_joint" type="continuous">
        <origin
                xyz="-0.0515749621984941 -0.1185 0.0170000000000001"
                rpy="0 0 0"/>
        <parent
                link="base_link"/>
        <child
                link="RB_wheel_link"/>
        <axis
                xyz="0 1 0"/>
    </joint>
    <link name="LF_wheel_link">
        <inertial>
            <origin
                    xyz="1.38777878078145E-17 -0.0144155178676929 -6.93889390390723E-18"
                    rpy="0 0 0"/>
            <mass
                    value="0.12660325610778"/>
            <inertia
                    ixx="5.54515308491946E-05"
                    ixy="1.11484803111754E-20"
                    ixz="3.63166728901572E-20"
                    iyy="0.000103691650811599"
                    iyz="-6.59731186397094E-22"
                    izz="5.54515308491945E-05"/>
        </inertial>
        <visual>
            <origin
                    xyz="0 0 0"
                    rpy="0 0 0"/>
            <geometry>
                <mesh
                        filename="package://arena_model/meshes/LF_wheel_link.STL"/>
            </geometry>
            <material
                    name="">
                <color
                        rgba="0.752941176470588 0.752941176470588 0.752941176470588 1"/>
            </material>
        </visual>
        <collision>
            <origin
                    xyz="0 0 0"
                    rpy="0 0 0"/>
            <geometry>
                <mesh
                        filename="package://arena_model/meshes/LF_wheel_link.STL"/>
            </geometry>
        </collision>
    </link>
    <joint name="LF_wheel_joint" type="continuous">
        <origin
                xyz="0.0784235230362503 0.1185 0.017"
                rpy="0 0 0"/>
        <parent
                link="base_link"/>
        <child
                link="LF_wheel_link"/>
        <axis
                xyz="0 1 0"/>
    </joint>
    <link name="LB_wheel_link">
        <inertial>
            <origin
                    xyz="-2.08166817117217E-17 -0.0144155178676929 -1.04083408558608E-17"
                    rpy="0 0 0"/>
            <mass
                    value="0.12660325610778"/>
            <inertia
                    ixx="5.54515308491946E-05"
                    ixy="1.12631967112259E-20"
                    ixz="5.00675004197287E-20"
                    iyy="0.000103691650811599"
                    iyz="-9.84080184560722E-22"
                    izz="5.54515308491945E-05"/>
        </inertial>
        <visual>
            <origin
                    xyz="0 0 0"
                    rpy="0 0 0"/>
            <geometry>
                <mesh
                        filename="package://arena_model/meshes/LB_wheel_link.STL"/>
            </geometry>
            <material
                    name="">
                <color
                        rgba="0.752941176470588 0.752941176470588 0.752941176470588 1"/>
            </material>
        </visual>
        <collision>
            <origin
                    xyz="0 0 0"
                    rpy="0 0 0"/>
            <geometry>
                <mesh
                        filename="package://arena_model/meshes/LB_wheel_link.STL"/>
            </geometry>
        </collision>
    </link>
    <joint
            name="LB_wheel_joint"
            type="continuous">
        <origin
                xyz="-0.0515749621984946 0.1185 0.017"
                rpy="0 0 0"/>
        <parent
                link="base_link"/>
        <child
                link="LB_wheel_link"/>
        <axis
                xyz="0 1 0"/>
    </joint>
    <link
            name="camera_link">
        <inertial>
            <origin
                    xyz="-0.02029 -5.2404E-18 -3.4694E-18"
                    rpy="0 0 0"/>
            <mass
                    value="0.074292"/>
            <inertia
                    ixx="6.2516E-06"
                    ixy="1.4512E-22"
                    ixz="-9.4055E-23"
                    iyy="9.6017E-06"
                    iyz="-6.6667E-23"
                    izz="1.1416E-05"/>
        </inertial>
        <visual>
            <origin
                    xyz="0 0 0"
                    rpy="0 0 0"/>
            <geometry>
                <mesh
                        filename="package://arena_model/meshes/camera_link.STL"/>
            </geometry>
            <material
                    name="">
                <color
                        rgba="0.75294 0.75294 0.75294 1"/>
            </material>
        </visual>
        <collision>
            <origin
                    xyz="0 0 0"
                    rpy="0 0 0"/>
            <geometry>
                <mesh
                        filename="package://arena_model/meshes/camera_link.STL"/>
            </geometry>
        </collision>
    </link>
    <joint
            name="camera_joint"
            type="fixed">
        <origin
                xyz="-0.0854500682801336 0 0.021"
                rpy="0 0 3.14159265358979"/>
        <parent
                link="base_link"/>
        <child
                link="camera_link"/>
        <axis
                xyz="0 0 0"/>
    </joint>
    <link
            name="R_range_link">
        <inertial>
            <origin
                    xyz="-0.0081193 -0.00018838 -0.01098"
                    rpy="0 0 0"/>
            <mass
                    value="0.0042661"/>
            <inertia
                    ixx="4.0735E-07"
                    ixy="-1.0722E-10"
                    ixz="-6.311E-10"
                    iyy="4.0797E-07"
                    iyz="-1.6467E-11"
                    izz="1.08E-07"/>
        </inertial>
        <visual>
            <origin
                    xyz="0 0 0"
                    rpy="0 0 0"/>
            <geometry>
                <mesh
                        filename="package://arena_model/meshes/R_range_link.STL"/>
            </geometry>
            <material
                    name="">
                <color
                        rgba="0.18039 0.18039 0.18039 1"/>
            </material>
        </visual>
        <collision>
            <origin
                    xyz="0 0 0"
                    rpy="0 0 0"/>
            <geometry>
                <mesh
                        filename="package://arena_model/meshes/R_range_link.STL"/>
            </geometry>
        </collision>
    </link>
    <joint
            name="R_range_joint"
            type="fixed">
        <origin
                xyz="0.0127112996311823 -0.1125 0.0392366"
                rpy="0 0 -1.5707963267949"/>
        <parent
                link="base_link"/>
        <child
                link="R_range_link"/>
        <axis
                xyz="0 0 0"/>
    </joint>
    <link
            name="L_range_link">
        <inertial>
            <origin
                    xyz="-0.0070193 0.00018838 -0.010032"
                    rpy="0 0 0"/>
            <mass
                    value="0.0042661"/>
            <inertia
                    ixx="4.0735E-07"
                    ixy="1.0722E-10"
                    ixz="6.311E-10"
                    iyy="4.0797E-07"
                    iyz="-1.6467E-11"
                    izz="1.08E-07"/>
        </inertial>
        <visual>
            <origin
                    xyz="0 0 0"
                    rpy="0 0 0"/>
            <geometry>
                <mesh
                        filename="package://arena_model/meshes/L_range_link.STL"/>
            </geometry>
            <material
                    name="">
                <color
                        rgba="0.18039 0.18039 0.18039 1"/>
            </material>
        </visual>
        <collision>
            <origin
                    xyz="0 0 0"
                    rpy="0 0 0"/>
            <geometry>
                <mesh
                        filename="package://arena_model/meshes/L_range_link.STL"/>
            </geometry>
        </collision>
    </link>
    <joint
            name="L_range_joint"
            type="fixed">
        <origin
                xyz="0.0123868089774774 0.1114 0.0382478433671816"
                rpy="0 0 1.5707963267949"/>
        <parent
                link="base_link"/>
        <child
                link="L_range_link"/>
        <axis
                xyz="0 0 0"/>
    </joint>
    <link
            name="RF_range_link">
        <inertial>
            <origin
                    xyz="-0.00731934334227206 -0.000188378653789074 -0.0109796493363324"
                    rpy="0 0 0"/>
            <mass
                    value="0.00426614745709292"/>
            <inertia
                    ixx="4.07348519263312E-07"
                    ixy="-1.07222949743676E-10"
                    ixz="-6.31099022040258E-10"
                    iyy="4.07971772782718E-07"
                    iyz="-1.64673276880206E-11"
                    izz="1.07995575989039E-07"/>
        </inertial>
        <visual>
            <origin
                    xyz="0 0 0"
                    rpy="0 0 0"/>
            <geometry>
                <mesh
                        filename="package://arena_model/meshes/RF_range_link.STL"/>
            </geometry>
            <material
                    name="">
                <color
                        rgba="0.180392156862745 0.180392156862745 0.180392156862745 1"/>
            </material>
        </visual>
        <collision>
            <origin
                    xyz="0 0 0"
                    rpy="0 0 0"/>
            <geometry>
                <mesh
                        filename="package://arena_model/meshes/RF_range_link.STL"/>
            </geometry>
        </collision>
    </link>
    <joint
            name="RF_range_joint"
            type="fixed">
        <origin
                xyz="0.095464280418878 -0.0534999999999997 0.0515"
                rpy="0 0 0"/>
        <parent
                link="base_link"/>
        <child
                link="RF_range_link"/>
        <axis
                xyz="0 0 0"/>
    </joint>
    <link
            name="RB_range_link">
        <inertial>
            <origin
                    xyz="-0.0070193 0.00018838 -0.010032"
                    rpy="0 0 0"/>
            <mass
                    value="0.0042661"/>
            <inertia
                    ixx="4.0735E-07"
                    ixy="1.0722E-10"
                    ixz="6.311E-10"
                    iyy="4.0797E-07"
                    iyz="-1.6467E-11"
                    izz="1.08E-07"/>
        </inertial>
        <visual>
            <origin
                    xyz="0 0 0"
                    rpy="0 0 0"/>
            <geometry>
                <mesh
                        filename="package://arena_model/meshes/RB_range_link.STL"/>
            </geometry>
            <material
                    name="">
                <color
                        rgba="0.18039 0.18039 0.18039 1"/>
            </material>
        </visual>
        <collision>
            <origin
                    xyz="0 0 0"
                    rpy="0 0 0"/>
            <geometry>
                <mesh
                        filename="package://arena_model/meshes/RB_range_link.STL"/>
            </geometry>
        </collision>
    </link>
    <joint
            name="RB_range_joint"
            type="fixed">
        <origin
                xyz="0.114521325155332 -0.0644999999999997 0.0252207965630269"
                rpy="0 0.785398163397454 0"/>
        <parent
                link="base_link"/>
        <child
                link="RB_range_link"/>
        <axis
                xyz="0 0 0"/>
    </joint>
    <link
            name="LF_range_link">
        <inertial>
            <origin
                    xyz="-0.0081193 -0.00018838 -0.01098"
                    rpy="0 0 0"/>
            <mass
                    value="0.0042661"/>
            <inertia
                    ixx="4.0735E-07"
                    ixy="-1.0722E-10"
                    ixz="-6.311E-10"
                    iyy="4.0797E-07"
                    iyz="-1.6467E-11"
                    izz="1.08E-07"/>
        </inertial>
        <visual>
            <origin
                    xyz="0 0 0"
                    rpy="0 0 0"/>
            <geometry>
                <mesh
                        filename="package://arena_model/meshes/LF_range_link.STL"/>
            </geometry>
            <material
                    name="">
                <color
                        rgba="0.18039 0.18039 0.18039 1"/>
            </material>
        </visual>
        <collision>
            <origin
                    xyz="0 0 0"
                    rpy="0 0 0"/>
            <geometry>
                <mesh
                        filename="package://arena_model/meshes/LF_range_link.STL"/>
            </geometry>
        </collision>
    </link>
    <joint
            name="LF_range_joint"
            type="fixed">
        <origin
                xyz="0.0962642804188774 0.0620922441262945 0.0515"
                rpy="0 0 0"/>
        <parent
                link="base_link"/>
        <child
                link="LF_range_link"/>
        <axis
                xyz="0 0 0"/>
    </joint>
    <link
            name="LB_range_link">
        <inertial>
            <origin
                    xyz="-0.0070193 0.00018838 -0.010032"
                    rpy="0 0 0"/>
            <mass
                    value="0.0042661"/>
            <inertia
                    ixx="4.0735E-07"
                    ixy="1.0722E-10"
                    ixz="6.311E-10"
                    iyy="4.0797E-07"
                    iyz="-1.6467E-11"
                    izz="1.08E-07"/>
        </inertial>
        <visual>
            <origin
                    xyz="0 0 0"
                    rpy="0 0 0"/>
            <geometry>
                <mesh
                        filename="package://arena_model/meshes/LB_range_link.STL"/>
            </geometry>
            <material
                    name="">
                <color
                        rgba="0.18039 0.18039 0.18039 1"/>
            </material>
        </visual>
        <collision>
            <origin
                    xyz="0 0 0"
                    rpy="0 0 0"/>
            <geometry>
                <mesh
                        filename="package://arena_model/meshes/LB_range_link.STL"/>
            </geometry>
        </collision>
    </link>
    <joint
            name="LB_range_joint"
            type="fixed">
        <origin
                xyz="0.114521325155331 0.0510922441262945 0.0252207965630269"
                rpy="0 0.785398163397454 0"/>
        <parent
                link="base_link"/>
        <child
                link="LB_range_link"/>
        <axis
                xyz="0 0 0"/>
    </joint>
</robot>